[2025-03-23T16:47:48.963+0000] {local_task_job_runner.py:123} INFO - ::group::Pre task execution logs
[2025-03-23T16:47:49.079+0000] {taskinstance.py:2614} INFO - Dependencies all met for dep_context=non-requeueable deps ti=<TaskInstance: dag_create_table.create_table scheduled__2025-03-18T08:00:00+00:00 [queued]>
[2025-03-23T16:47:49.173+0000] {taskinstance.py:2614} INFO - Dependencies all met for dep_context=requeueable deps ti=<TaskInstance: dag_create_table.create_table scheduled__2025-03-18T08:00:00+00:00 [queued]>
[2025-03-23T16:47:49.185+0000] {taskinstance.py:2867} INFO - Starting attempt 1 of 1
[2025-03-23T16:47:51.223+0000] {taskinstance.py:2890} INFO - Executing <Task(PythonOperator): create_table> on 2025-03-18 08:00:00+00:00
[2025-03-23T16:47:51.261+0000] {standard_task_runner.py:72} INFO - Started process 240 to run task
[2025-03-23T16:47:51.293+0000] {standard_task_runner.py:104} INFO - Running: ['airflow', 'tasks', 'run', 'dag_create_table', 'create_table', 'scheduled__2025-03-18T08:00:00+00:00', '--job-id', '1817', '--raw', '--subdir', 'DAGS_FOLDER/dag_create_table.py', '--cfg-path', '/tmp/tmp706v0ike']
[2025-03-23T16:47:51.306+0000] {standard_task_runner.py:105} INFO - Job 1817: Subtask create_table
[2025-03-23T16:47:51.482+0000] {logging_mixin.py:190} WARNING - /home/airflow/.local/lib/python3.8/site-packages/airflow/settings.py:209 DeprecationWarning: The sql_alchemy_conn option in [core] has been moved to the sql_alchemy_conn option in [database] - the old setting has been used, but please update your config.
[2025-03-23T16:47:52.602+0000] {task_command.py:467} INFO - Running <TaskInstance: dag_create_table.create_table scheduled__2025-03-18T08:00:00+00:00 [running]> on host 475a27c70afe
[2025-03-23T16:47:52.667+0000] {logging_mixin.py:190} WARNING - /home/airflow/.local/lib/python3.8/site-packages/airflow/settings.py:470 DeprecationWarning: The sql_alchemy_conn option in [core] has been moved to the sql_alchemy_conn option in [database] - the old setting has been used, but please update your config.
[2025-03-23T16:47:53.856+0000] {taskinstance.py:3134} INFO - Exporting env vars: AIRFLOW_CTX_DAG_OWNER='airflow' AIRFLOW_CTX_DAG_ID='dag_create_table' AIRFLOW_CTX_TASK_ID='create_table' AIRFLOW_CTX_EXECUTION_DATE='2025-03-18T08:00:00+00:00' AIRFLOW_CTX_TRY_NUMBER='1' AIRFLOW_CTX_DAG_RUN_ID='scheduled__2025-03-18T08:00:00+00:00'
[2025-03-23T16:47:53.942+0000] {taskinstance.py:732} INFO - ::endgroup::
[2025-03-23T16:47:55.670+0000] {logging_mixin.py:190} INFO - Job iniciado com sucesso. Run ID: 78792716854995
[2025-03-23T16:52:20.464+0000] {taskinstance.py:3313} ERROR - Task failed with exception
Traceback (most recent call last):
  File "/home/airflow/.local/lib/python3.8/site-packages/urllib3/connection.py", line 174, in _new_conn
    conn = connection.create_connection(
  File "/home/airflow/.local/lib/python3.8/site-packages/urllib3/util/connection.py", line 72, in create_connection
    for res in socket.getaddrinfo(host, port, family, socket.SOCK_STREAM):
  File "/usr/local/lib/python3.8/socket.py", line 918, in getaddrinfo
    for res in _socket.getaddrinfo(host, port, family, type, proto, flags):
socket.gaierror: [Errno -3] Temporary failure in name resolution

During handling of the above exception, another exception occurred:

Traceback (most recent call last):
  File "/home/airflow/.local/lib/python3.8/site-packages/urllib3/connectionpool.py", line 703, in urlopen
    httplib_response = self._make_request(
  File "/home/airflow/.local/lib/python3.8/site-packages/urllib3/connectionpool.py", line 386, in _make_request
    self._validate_conn(conn)
  File "/home/airflow/.local/lib/python3.8/site-packages/urllib3/connectionpool.py", line 1042, in _validate_conn
    conn.connect()
  File "/home/airflow/.local/lib/python3.8/site-packages/urllib3/connection.py", line 363, in connect
    self.sock = conn = self._new_conn()
  File "/home/airflow/.local/lib/python3.8/site-packages/urllib3/connection.py", line 186, in _new_conn
    raise NewConnectionError(
urllib3.exceptions.NewConnectionError: <urllib3.connection.HTTPSConnection object at 0xffffa41d1340>: Failed to establish a new connection: [Errno -3] Temporary failure in name resolution

During handling of the above exception, another exception occurred:

Traceback (most recent call last):
  File "/home/airflow/.local/lib/python3.8/site-packages/requests/adapters.py", line 486, in send
    resp = conn.urlopen(
  File "/home/airflow/.local/lib/python3.8/site-packages/urllib3/connectionpool.py", line 787, in urlopen
    retries = retries.increment(
  File "/home/airflow/.local/lib/python3.8/site-packages/urllib3/util/retry.py", line 592, in increment
    raise MaxRetryError(_pool, url, error or ResponseError(cause))
urllib3.exceptions.MaxRetryError: HTTPSConnectionPool(host='adb-2740266284098548.8.azuredatabricks.net', port=443): Max retries exceeded with url: /api/2.0/jobs/runs/get?run_id=78792716854995 (Caused by NewConnectionError('<urllib3.connection.HTTPSConnection object at 0xffffa41d1340>: Failed to establish a new connection: [Errno -3] Temporary failure in name resolution'))

During handling of the above exception, another exception occurred:

Traceback (most recent call last):
  File "/home/airflow/.local/lib/python3.8/site-packages/airflow/models/taskinstance.py", line 768, in _execute_task
    result = _execute_callable(context=context, **execute_callable_kwargs)
  File "/home/airflow/.local/lib/python3.8/site-packages/airflow/models/taskinstance.py", line 734, in _execute_callable
    return ExecutionCallableRunner(
  File "/home/airflow/.local/lib/python3.8/site-packages/airflow/utils/operator_helpers.py", line 252, in run
    return self.func(*args, **kwargs)
  File "/home/airflow/.local/lib/python3.8/site-packages/airflow/models/baseoperator.py", line 424, in wrapper
    return func(self, *args, **kwargs)
  File "/home/airflow/.local/lib/python3.8/site-packages/airflow/operators/python.py", line 238, in execute
    return_value = self.execute_callable()
  File "/home/airflow/.local/lib/python3.8/site-packages/airflow/operators/python.py", line 256, in execute_callable
    return runner.run(*self.op_args, **self.op_kwargs)
  File "/home/airflow/.local/lib/python3.8/site-packages/airflow/utils/operator_helpers.py", line 252, in run
    return self.func(*args, **kwargs)
  File "/opt/airflow/dags/dag_create_table.py", line 43, in trigger_and_wait_create_table
    wait_for_job_to_finish(run_id, databricks_url, databricks_token)
  File "/opt/airflow/dags/conf/utils.py", line 42, in wait_for_job_to_finish
    response = requests.get(run_status_url, headers=headers, params={"run_id": run_id})
  File "/home/airflow/.local/lib/python3.8/site-packages/requests/api.py", line 73, in get
    return request("get", url, params=params, **kwargs)
  File "/home/airflow/.local/lib/python3.8/site-packages/requests/api.py", line 59, in request
    return session.request(method=method, url=url, **kwargs)
  File "/home/airflow/.local/lib/python3.8/site-packages/requests/sessions.py", line 587, in request
    resp = self.send(prep, **send_kwargs)
  File "/home/airflow/.local/lib/python3.8/site-packages/requests/sessions.py", line 701, in send
    r = adapter.send(request, **kwargs)
  File "/home/airflow/.local/lib/python3.8/site-packages/requests/adapters.py", line 519, in send
    raise ConnectionError(e, request=request)
requests.exceptions.ConnectionError: HTTPSConnectionPool(host='adb-2740266284098548.8.azuredatabricks.net', port=443): Max retries exceeded with url: /api/2.0/jobs/runs/get?run_id=78792716854995 (Caused by NewConnectionError('<urllib3.connection.HTTPSConnection object at 0xffffa41d1340>: Failed to establish a new connection: [Errno -3] Temporary failure in name resolution'))
[2025-03-23T16:53:00.967+0000] {job.py:229} INFO - Heartbeat recovered after 62.77 seconds
[2025-03-23T16:53:03.354+0000] {taskinstance.py:1226} INFO - Marking task as FAILED. dag_id=dag_create_table, task_id=create_table, run_id=scheduled__2025-03-18T08:00:00+00:00, execution_date=20250318T080000, start_date=20250323T164749, end_date=20250323T165302
[2025-03-23T16:53:04.200+0000] {taskinstance.py:341} INFO - ::group::Post task execution logs
[2025-03-23T16:53:04.302+0000] {standard_task_runner.py:124} ERROR - Failed to execute job 1817 for task create_table (HTTPSConnectionPool(host='adb-2740266284098548.8.azuredatabricks.net', port=443): Max retries exceeded with url: /api/2.0/jobs/runs/get?run_id=78792716854995 (Caused by NewConnectionError('<urllib3.connection.HTTPSConnection object at 0xffffa41d1340>: Failed to establish a new connection: [Errno -3] Temporary failure in name resolution')); 240)
Traceback (most recent call last):
  File "/home/airflow/.local/lib/python3.8/site-packages/urllib3/connection.py", line 174, in _new_conn
    conn = connection.create_connection(
  File "/home/airflow/.local/lib/python3.8/site-packages/urllib3/util/connection.py", line 72, in create_connection
    for res in socket.getaddrinfo(host, port, family, socket.SOCK_STREAM):
  File "/usr/local/lib/python3.8/socket.py", line 918, in getaddrinfo
    for res in _socket.getaddrinfo(host, port, family, type, proto, flags):
socket.gaierror: [Errno -3] Temporary failure in name resolution

During handling of the above exception, another exception occurred:

Traceback (most recent call last):
  File "/home/airflow/.local/lib/python3.8/site-packages/urllib3/connectionpool.py", line 703, in urlopen
    httplib_response = self._make_request(
  File "/home/airflow/.local/lib/python3.8/site-packages/urllib3/connectionpool.py", line 386, in _make_request
    self._validate_conn(conn)
  File "/home/airflow/.local/lib/python3.8/site-packages/urllib3/connectionpool.py", line 1042, in _validate_conn
    conn.connect()
  File "/home/airflow/.local/lib/python3.8/site-packages/urllib3/connection.py", line 363, in connect
    self.sock = conn = self._new_conn()
  File "/home/airflow/.local/lib/python3.8/site-packages/urllib3/connection.py", line 186, in _new_conn
    raise NewConnectionError(
urllib3.exceptions.NewConnectionError: <urllib3.connection.HTTPSConnection object at 0xffffa41d1340>: Failed to establish a new connection: [Errno -3] Temporary failure in name resolution

During handling of the above exception, another exception occurred:

Traceback (most recent call last):
  File "/home/airflow/.local/lib/python3.8/site-packages/requests/adapters.py", line 486, in send
    resp = conn.urlopen(
  File "/home/airflow/.local/lib/python3.8/site-packages/urllib3/connectionpool.py", line 787, in urlopen
    retries = retries.increment(
  File "/home/airflow/.local/lib/python3.8/site-packages/urllib3/util/retry.py", line 592, in increment
    raise MaxRetryError(_pool, url, error or ResponseError(cause))
urllib3.exceptions.MaxRetryError: HTTPSConnectionPool(host='adb-2740266284098548.8.azuredatabricks.net', port=443): Max retries exceeded with url: /api/2.0/jobs/runs/get?run_id=78792716854995 (Caused by NewConnectionError('<urllib3.connection.HTTPSConnection object at 0xffffa41d1340>: Failed to establish a new connection: [Errno -3] Temporary failure in name resolution'))

During handling of the above exception, another exception occurred:

Traceback (most recent call last):
  File "/home/airflow/.local/lib/python3.8/site-packages/airflow/task/task_runner/standard_task_runner.py", line 117, in _start_by_fork
    ret = args.func(args, dag=self.dag)
  File "/home/airflow/.local/lib/python3.8/site-packages/airflow/cli/cli_config.py", line 49, in command
    return func(*args, **kwargs)
  File "/home/airflow/.local/lib/python3.8/site-packages/airflow/utils/cli.py", line 116, in wrapper
    return f(*args, **kwargs)
  File "/home/airflow/.local/lib/python3.8/site-packages/airflow/cli/commands/task_command.py", line 483, in task_run
    task_return_code = _run_task_by_selected_method(args, _dag, ti)
  File "/home/airflow/.local/lib/python3.8/site-packages/airflow/cli/commands/task_command.py", line 256, in _run_task_by_selected_method
    return _run_raw_task(args, ti)
  File "/home/airflow/.local/lib/python3.8/site-packages/airflow/cli/commands/task_command.py", line 341, in _run_raw_task
    return ti._run_raw_task(
  File "/home/airflow/.local/lib/python3.8/site-packages/airflow/utils/session.py", line 97, in wrapper
    return func(*args, session=session, **kwargs)
  File "/home/airflow/.local/lib/python3.8/site-packages/airflow/models/taskinstance.py", line 3006, in _run_raw_task
    return _run_raw_task(
  File "/home/airflow/.local/lib/python3.8/site-packages/airflow/models/taskinstance.py", line 274, in _run_raw_task
    TaskInstance._execute_task_with_callbacks(
  File "/home/airflow/.local/lib/python3.8/site-packages/airflow/models/taskinstance.py", line 3161, in _execute_task_with_callbacks
    result = self._execute_task(context, task_orig)
  File "/home/airflow/.local/lib/python3.8/site-packages/airflow/models/taskinstance.py", line 3185, in _execute_task
    return _execute_task(self, context, task_orig)
  File "/home/airflow/.local/lib/python3.8/site-packages/airflow/models/taskinstance.py", line 768, in _execute_task
    result = _execute_callable(context=context, **execute_callable_kwargs)
  File "/home/airflow/.local/lib/python3.8/site-packages/airflow/models/taskinstance.py", line 734, in _execute_callable
    return ExecutionCallableRunner(
  File "/home/airflow/.local/lib/python3.8/site-packages/airflow/utils/operator_helpers.py", line 252, in run
    return self.func(*args, **kwargs)
  File "/home/airflow/.local/lib/python3.8/site-packages/airflow/models/baseoperator.py", line 424, in wrapper
    return func(self, *args, **kwargs)
  File "/home/airflow/.local/lib/python3.8/site-packages/airflow/operators/python.py", line 238, in execute
    return_value = self.execute_callable()
  File "/home/airflow/.local/lib/python3.8/site-packages/airflow/operators/python.py", line 256, in execute_callable
    return runner.run(*self.op_args, **self.op_kwargs)
  File "/home/airflow/.local/lib/python3.8/site-packages/airflow/utils/operator_helpers.py", line 252, in run
    return self.func(*args, **kwargs)
  File "/opt/airflow/dags/dag_create_table.py", line 43, in trigger_and_wait_create_table
    wait_for_job_to_finish(run_id, databricks_url, databricks_token)
  File "/opt/airflow/dags/conf/utils.py", line 42, in wait_for_job_to_finish
    response = requests.get(run_status_url, headers=headers, params={"run_id": run_id})
  File "/home/airflow/.local/lib/python3.8/site-packages/requests/api.py", line 73, in get
    return request("get", url, params=params, **kwargs)
  File "/home/airflow/.local/lib/python3.8/site-packages/requests/api.py", line 59, in request
    return session.request(method=method, url=url, **kwargs)
  File "/home/airflow/.local/lib/python3.8/site-packages/requests/sessions.py", line 587, in request
    resp = self.send(prep, **send_kwargs)
  File "/home/airflow/.local/lib/python3.8/site-packages/requests/sessions.py", line 701, in send
    r = adapter.send(request, **kwargs)
  File "/home/airflow/.local/lib/python3.8/site-packages/requests/adapters.py", line 519, in send
    raise ConnectionError(e, request=request)
requests.exceptions.ConnectionError: HTTPSConnectionPool(host='adb-2740266284098548.8.azuredatabricks.net', port=443): Max retries exceeded with url: /api/2.0/jobs/runs/get?run_id=78792716854995 (Caused by NewConnectionError('<urllib3.connection.HTTPSConnection object at 0xffffa41d1340>: Failed to establish a new connection: [Errno -3] Temporary failure in name resolution'))
[2025-03-23T16:53:04.458+0000] {local_task_job_runner.py:266} INFO - Task exited with return code 1
[2025-03-23T16:53:04.719+0000] {standard_task_runner.py:217} INFO - Process not found (most likely exited), stop collecting metrics
[2025-03-23T16:53:05.143+0000] {taskinstance.py:3901} INFO - 0 downstream tasks scheduled from follow-on schedule check
[2025-03-23T16:53:05.198+0000] {local_task_job_runner.py:245} INFO - ::endgroup::
